<?xml version="1.0"?>
<robot xmlns:xacro="http://www.ros.org/wiki/xacro" name="summit_xl">

    <!-- Define materials -->
    <material name="blue">
        <color rgba="0 0 1 1"/>
    </material>

    <material name="black">
        <color rgba="0 0 0 1"/>
    </material>

    <material name="red">
        <color rgba="1 0 0 1"/>
    </material>

    <!-- Gazebo materials for colors -->
    <gazebo reference="base_link">
        <material>Gazebo/Blue</material>
    </gazebo>

    <gazebo reference="summit_front_right_wheel_link">
        <material>Gazebo/Black</material>
    </gazebo>

    <gazebo reference="summit_front_left_wheel_link">
        <material>Gazebo/Black</material>
    </gazebo>

    <gazebo reference="summit_back_left_wheel_link">
        <material>Gazebo/Black</material>
    </gazebo>

    <gazebo reference="summit_back_right_wheel_link">
        <material>Gazebo/Black</material>
    </gazebo>

    <gazebo reference="lidar_link">
        <material>Gazebo/Grey</material>
    </gazebo>

    <gazebo reference="camera_link">
        <material>Gazebo/Red</material>
    </gazebo>

    <!-- Virtual frames for TF tree -->
    <link name="map"/>
    <link name="odom"/>
    <link name="base_footprint"/>

    <!-- TF tree connections -->
    <joint name="map_to_odom" type="fixed">
        <parent link="map"/>
        <child link="odom"/>
        <origin xyz="0 0 0" rpy="0 0 0"/>
    </joint>

    <joint name="odom_to_base_footprint" type="fixed">
        <parent link="odom"/>
        <child link="base_footprint"/>
        <origin xyz="0 0 0" rpy="0 0 0"/>
    </joint>

    <joint name="base_joint" type="fixed">
        <parent link="base_footprint"/>
        <child link="base_link"/>
        <origin xyz="0 0 0.010" rpy="0 0 0"/>
    </joint>

    <!-- Base link -->
    <link name="base_link">
        <inertial>
            <mass value="10.0"/>
            <origin xyz="0 0 0" rpy="0 0 0"/>
            <inertia ixx="0.1" ixy="0.0" ixz="0.0" iyy="0.1" iyz="0.0" izz="0.1"/>
        </inertial>
        <visual>
            <geometry>
                <box size="0.268 0.247 0.13"/>
            </geometry>
            <material name="blue"/>
        </visual>
        <collision>
            <geometry>
                <box size="0.268 0.247 0.1"/>
            </geometry>
        </collision>
    </link>

    <!-- Wheels -->
    <!-- Front Right Wheel -->
    <link name="summit_front_right_wheel_link">
        <inertial>
            <mass value="1.0"/>
            <origin xyz="0 0 0" rpy="0 0 0"/>
            <inertia ixx="0.01" ixy="0.0" ixz="0.0" iyy="0.01" iyz="0.0" izz="0.01"/>
        </inertial>
        <visual>
            <geometry>
                <cylinder length="0.1" radius="0.07"/>
            </geometry>
            <material name="black"/>
        </visual>
        <collision>
            <geometry>
                <cylinder length="0.1" radius="0.07"/>
            </geometry>
        </collision>
    </link>

    <joint name="summit_front_right_wheel_joint" type="continuous">
        <parent link="base_link"/>
        <child link="summit_front_right_wheel_link"/>
        <origin xyz="0.1 -0.173 -0.05" rpy="1.57 0 0"/>
        <axis xyz="0 0 1"/>
    </joint>

    <!-- Front Left Wheel -->
    <link name="summit_front_left_wheel_link">
        <inertial>
            <mass value="1.0"/>
            <origin xyz="0 0 0" rpy="0 0 0"/>
            <inertia ixx="0.01" ixy="0.0" ixz="0.0" iyy="0.01" iyz="0.0" izz="0.01"/>
        </inertial>
        <visual>
            <geometry>
                <cylinder length="0.1" radius="0.07"/>
            </geometry>
            <material name="black"/>
        </visual>
        <collision>
            <geometry>
                <cylinder length="0.1" radius="0.07"/>
            </geometry>
        </collision>
    </link>

    <joint name="summit_front_left_wheel_joint" type="continuous">
        <parent link="base_link"/>
        <child link="summit_front_left_wheel_link"/>
        <origin xyz="0.1 0.173 -0.05" rpy="1.57 0 0"/>
        <axis xyz="0 0 1"/>
    </joint>

    <!-- Back Left Wheel -->
    <link name="summit_back_left_wheel_link">
        <inertial>
            <mass value="1.0"/>
            <origin xyz="0 0 0" rpy="0 0 0"/>
            <inertia ixx="0.01" ixy="0.0" ixz="0.0" iyy="0.01" iyz="0.0" izz="0.01"/>
        </inertial>
        <visual>
            <geometry>
                <cylinder length="0.1" radius="0.07"/>
            </geometry>
            <material name="black"/>
        </visual>
        <collision>
            <geometry>
                <cylinder length="0.1" radius="0.07"/>
            </geometry>
        </collision>
    </link>

    <joint name="summit_back_left_wheel_joint" type="continuous">
        <parent link="base_link"/>
        <child link="summit_back_left_wheel_link"/>
        <origin xyz="-0.1 0.173 -0.05" rpy="1.57 0 0"/>
        <axis xyz="0 0 1"/>
    </joint>

    <!-- Back Right Wheel -->
    <link name="summit_back_right_wheel_link">
        <inertial>
            <mass value="1.0"/>
            <origin xyz="0 0 0" rpy="0 0 0"/>
            <inertia ixx="0.01" ixy="0.0" ixz="0.0" iyy="0.01" iyz="0.0" izz="0.01"/>
        </inertial>
        <visual>
            <geometry>
                <cylinder length="0.1" radius="0.07"/>
            </geometry>
            <material name="black"/>
        </visual>
        <collision>
            <geometry>
                <cylinder length="0.1" radius="0.07"/>
            </geometry>
        </collision>
    </link>

    <joint name="summit_back_right_wheel_joint" type="continuous">
        <parent link="base_link"/>
        <child link="summit_back_right_wheel_link"/>
        <origin xyz="-0.1 -0.173 -0.05" rpy="1.57 0 0"/>
        <axis xyz="0 0 1"/>
    </joint>

    <!-- Sensors -->
    <!-- LiDAR Sensor -->
    <link name="lidar_link">
        <visual>
            <geometry>
                <cylinder radius="0.05" length="0.05"/>
            </geometry>
            <material name="red"/>
        </visual>
        <collision>
            <geometry>
                <cylinder radius="0.05" length="0.05"/>
            </geometry>
        </collision>
        <inertial>
            <mass value="0.2"/>
            <origin xyz="0 0 0" rpy="0 0 0"/>
            <inertia ixx="0.01" ixy="0" ixz="0" iyy="0.01" iyz="0" izz="0.01"/>
        </inertial>
    </link>

    <joint name="summit_lidar_joint" type="fixed">
        <parent link="base_link"/>
        <child link="lidar_link"/>
        <origin xyz="0 0 0.15" rpy="0 0 0"/>
    </joint>

    <!-- Camera -->
    <link name="camera_link">
        <visual>
            <geometry>
                <box size="0.05 0.05 0.05"/>
            </geometry>
            <material name="black"/>
        </visual>
        <collision>
            <geometry>
                <box size="0.05 0.05 0.05"/>
            </geometry>
        </collision>
        <inertial>
            <mass value="0.1"/>
            <origin xyz="0 0 0" rpy="0 0 0"/>
            <inertia ixx="0.01" ixy="0.0" ixz="0.0" iyy="0.01" iyz="0.0" izz="0.01"/>
        </inertial>
    </link>

    <joint name="camera_joint" type="fixed">
        <parent link="lidar_link"/>
        <child link="camera_link"/>
        <origin xyz="0 0 0.1" rpy="0 0 3.14"/>
    </joint>

    <!-- Gazebo plugins -->
    <gazebo>
        <!-- Disable default robot state publisher -->
        <plugin name="gazebo_ros_control" filename="libgazebo_ros_control.so">
            <robotNamespace>/</robotNamespace>
            <robotSimType>gazebo_ros_control/DefaultRobotHWSim</robotSimType>
        </plugin>
    </gazebo>

    <gazebo reference="lidar_link">
        <sensor name="lidar_sensor" type="ray">
            <pose>0 0 0 0 0 0</pose>
            <visualize>true</visualize>
            <update_rate>5</update_rate>
            <ray>
                <scan>
                    <horizontal>
                        <samples>360</samples>
                        <resolution>1</resolution>
                        <min_angle>-3.14159</min_angle>
                        <max_angle>3.14159</max_angle>
                    </horizontal>
                </scan>
                <range>
                    <min>0.1</min>
                    <max>10.0</max>
                    <resolution>0.01</resolution>
                </range>
            </ray>
            <plugin name="gazebo_ros_lidar_controller" filename="libgazebo_ros_ray_sensor.so">
                <ros>
                    <namespace>/</namespace>
                    <remapping>~/out:=scan</remapping>
                </ros>
                <output_type>sensor_msgs/LaserScan</output_type>
                <frame_name>lidar_link</frame_name>
                <radiation_type>infrared</radiation_type>
            </plugin>
        </sensor>
    </gazebo>

    <gazebo reference="camera_link">
        <sensor name="camera_sensor" type="camera">
            <pose>0 0 0 0 0 0</pose>
            <visualize>true</visualize>
            <update_rate>30</update_rate>
            <camera>
                <horizontal_fov>1.0472</horizontal_fov>
                <image>
                    <width>640</width>
                    <height>480</height>
                    <format>R8G8B8</format>
                </image>
                <clip>
                    <near>0.1</near>
                    <far>100</far>
                </clip>
            </camera>
            <plugin name="camera_controller" filename="libgazebo_ros_camera.so">
                <ros>
                    <namespace>/</namespace>
                    <remapping>image_raw:=camera/image_raw</remapping>
                    <remapping>camera_info:=camera/camera_info</remapping>
                </ros>
                <camera_name>camera</camera_name>
                <frame_name>camera_link</frame_name>
                <hack_baseline>0.07</hack_baseline>
            </plugin>
        </sensor>
    </gazebo>

    <!-- Differential Drive Plugin -->
    <gazebo>
        <plugin name="differential_drive_controller" filename="libgazebo_ros_diff_drive.so">
            <ros>
                <namespace>/</namespace>
            </ros>
            <left_joint>summit_front_right_wheel_joint</left_joint>
            <right_joint>summit_front_left_wheel_joint</right_joint>
            <wheel_separation>0.346</wheel_separation>
            <wheel_diameter>0.14</wheel_diameter>
            <torque>10</torque>
            <command_topic>cmd_vel</command_topic>
            <odometry_topic>odom</odometry_topic>
            <odometry_frame>odom</odometry_frame>
            <robot_base_frame>base_footprint</robot_base_frame>
            <publish_odom>true</publish_odom>
            <publish_odom_tf>true</publish_odom_tf>
            <publish_wheel_tf>false</publish_wheel_tf> <!-- Changed to false -->
            <update_rate>30</update_rate>
        </plugin>
    </gazebo>

    <!-- Joint State Publisher -->
    <gazebo>
        <plugin name="joint_state_controller" filename="libgazebo_ros_joint_state_publisher.so">
            <ros>
                <namespace>/</namespace>
            </ros>
            <update_rate>30</update_rate>
            <joint_name>summit_front_left_wheel_joint</joint_name>
            <joint_name>summit_front_right_wheel_joint</joint_name>
            <joint_name>summit_back_left_wheel_joint</joint_name>
            <joint_name>summit_back_right_wheel_joint</joint_name>
            <joint_name>summit_lidar_joint</joint_name>
        </plugin>
    </gazebo>

</robot>